Workbook
Name billion: #REF!
Name billion: #REF!
Name Diesel_FE_2024: #REF!
Name Diesel_Sales_2024: #REF!
Name Eno_TM: #REF!
Name Eno_TM: #REF!
Name Eno_TM: #REF!
Name Eno_TM: #REF!
Name Eno_TM: #REF!
Name Eno_Tons: #REF!
Name Eno_Tons: #REF!
Name Eno_Tons: #REF!
Name Eno_Tons: #REF!
Name Eno_Tons: #REF!
Name EV_FE_2024: #REF!
Name EV_Sales_2024: #REF!
Name Fuel_Economies: #REF!
Name Gasoline_FE_2024: #REF!
Name Gasoline_Sales_2024: #REF!
Name Hydg_FE_2024: #REF!
Name Hydg_Sales_2024: #REF!
Name LPG_FE_2024: #REF!
Name LPG_Sales_2024: #REF!
Name NG_FE_2024: #REF!
Name NG_Sales_2024: #REF!
Name NTS_YR: #REF!
Name NTS_YR: About!$B$106
Name PHEV_FE_2024: #REF!
Name PHEV_Sales_2024: #REF!
Name Sales: #REF!
Name Sales_2024: #REF!
Name Sales_2025: #REF!
Name Sales_2026: #REF!
Name Sales_2027: #REF!
Name Sales_2028: #REF!
Name Sales_2029: #REF!
Name Standards: #REF!
Name Sum_T2: #REF!
Name Sum_T2: #REF!
Name Sum_T2: #REF!
Name Sum_T2: #REF!
Name Sum_T2: #REF!
Name Sum_TTM: #REF!
Name Sum_TTM: #REF!
Name Sum_TTM: #REF!
Name Sum_TTM: #REF!
Name Sum_TTM: #REF!
Name ti_tbl_50: #REF!
Name ti_tbl_50: #REF!
Name ti_tbl_50: #REF!
Name ti_tbl_50: #REF!
Name ti_tbl_50: #REF!
Name ti_tbl_69: #REF!
Name ti_tbl_69: #REF!
Name ti_tbl_69: #REF!
Name ti_tbl_69: #REF!
Name ti_tbl_69: #REF!
Name trillion: #REF!
Name trillion: #REF!

Sheet About
A1: Active state name: | B1: Mississippi | C1: 46266
A2: Active state code: | B2: =INDEX(Geography!$A$2:$A$49,MATCH($B$1,Geography!$B$2:$B$49,0)) -> MS
A5: BNVFE BAU New Vehicle Fuel Economy
A7: Sources: | B7: See Notes section for which vehicle types use which sources
B8: U.S. Energy Information Administration
B9: 2026
B10: Annual Energy Outlook 2026
B11: Scenario: Alternative Electricity and Transportation
B12: https://www.eia.gov/outlooks/aeo/tables_side_xls.php
B13: Tables 7, 35, 36, 38, 40, 47, 48, 49
B15: Bureau of Transportation Statistics
B16: 2017
B17: National Transportation Statistics
B18: https://www.rita.dot.gov/bts/sites/rita.dot.gov.bts/files/publications/national_transportation_statistics/index.html
B19: Table 1-40
B21: U.S. Coast Guard
B22: 2013
B23: National Recreational Boating Survey 2012
B24: http://www.uscgboating.org/library/recreational-boating-servey/2012survey%20report.pdf
B25: Page 63, Table 40
B27: U.S. Department of Energy
B28: 2015
B29: Fuel Cells Fact Sheet
B30: https://www.energy.gov/sites/prod/files/2015/11/f27/fcto_fuel_cells_fact_sheet.pdf
B32: U.S EPA
B33: 2022
B34: Automotive Trends Data
B35: https://www.epa.gov/automotive-trends/explore-automotive-trends-data#DetailedData
B37: Others as noted on "Calculations Etc" tab
B39: Passenger rail diesel vs. electric efficiency
B40: Environmental and Energy Study Institute
B41: 2018
B42: Electrification of U.S. Railways: Pie in the Sky, or Realistic Goal?
B43: https://www.eesi.org/articles/view/electrification-of-u.s.-railways-pie-in-the-sky-or-realistic-goal
B44: Third paragraph
A46: Notes
A47: This variable gives fuel economy for new vehicles in units of cargo distance per BTU.
A49: passenger LDVs
A50: Sources: AEO 7, AEO 40, CARB LEV III standards, others as noted on "Calculations Etc" tab
A51: The AEO provides new vehicle fuel economy in mpge terms. For each of the 7 EPS technologies, we take a weighted average of EIA's listed new vehicle
...

Sheet Geography
A1: state_abbr | B1: state_name
A2: AL | B2: Alabama
A3: AR | B3: Arkansas
A4: AZ | B4: Arizona
A5: CA | B5: California
A6: CO | B6: Colorado
A7: CT | B7: Connecticut
A8: DE | B8: Delaware
A9: FL | B9: Florida
A10: GA | B10: Georgia
A11: IA | B11: Iowa
A12: ID | B12: Idaho
... A49: WY | B49: Wyoming

Sheet source data>

Sheet AEO 2023 Table 7
B1: ref2023.d020623a | C1: 2022 | D1: 2023 | E1: 2024 | F1: 2025 | G1: 2026 | H1: 2027 | I1: 2028 | J1: 2029 | K1: 2030 | L1: 2031 | M1: 2032 | N1: 2033 | O1: 2034 | P1: 2035 | Q1: 2036 | R1: 2037 | S1: 2038 | T1: 2039 | U1: 2040 | V1: 2041 | W1: 2042 | X1: 2043 | Y1: 2044 | Z1: 2045 | AA1: 2046 | AB1: 2047 | AC1: 2048 | AD1: 2049 | AE1: 2050
C3: Report | D3: Annual Energy Outlook 2023
C4: Scenario | D4: ref2023 | G4: Reference
C5: Datekey | D5: d020623a
C6: Release Date | E6: March 2023
A10: TKI000 | B10: 7. Transportation Sector Key Indicators and Delivered Energy Consumption | AF10: Average
AF11: Annual
AF12: Change
B13: Key Indicators and Consumption | C13: 2022 | D13: 2023 | E13: 2024 | F13: 2025 | G13: 2026 | H13: 2027 | I13: 2028 | J13: 2029 | K13: 2030 | L13: 2031 | M13: 2032 | N13: 2033 | O13: 2034 | P13: 2035 | Q13: 2036 | R13: 2037 | S13: 2038 | T13: 2039 | U13: 2040 | V13: 2041 | W13: 2042 | X13: 2043 | Y13: 2044 | Z13: 2045 | AA13: 2046 | AB13: 2047 | AC13: 2048 | AD13: 2049 | AE13: 2050 | AF13: 2022–2050
B15: Key Indicators
B16: Travel Indicators
B17: (billion vehicle miles traveled)
A18: TKI000:ba_Light-DutyVeh | B18: Light-Duty Vehicles less than 8,501 pounds | C18: 2843.2981 | D18: 2901.3589 | E18: 2922.5066 | F18: 2933.3601 | G18: 2954.238 | H18: 2981.9343 | I18: 3007.5581 | J18: 3027.573 | K18: 3042.8433 | L18: 3055.7747 | M18: 3066.6516 | N18: 3082.3594 | O18: 3102.4182 | P18: 3120.7375 | Q18: 3135.6208 | R18: 3152.9177 | S18: 3172.4355 | T18: 3192.1006 | U18: 3214.563 | V18: 3237.5806 | W18: 3261.5847 | X18: 3284.8975 | Y18: 3309.0391 | Z18: 3334.7034 | AA18: 3364.5225 | AB18: 3396.5352 | AC18: 3429.5627 | AD18: 3463.0249 | AE18: 3499.543 | AF18: 0.007444
A19: TKI000:ba_CommercialLig | B19: Commercial Light Trucks 1/ | C19: 102.21495 | D19: 103.34346 | E19: 103.55378 | F19: 104.36999 | G19: 105.65627 | H19: 107.00255 | I19: 108.20406 | J19: 109.32984 | K19: 110.21457 | L19: 111.0637 | M19: 112.17591 | N19: 113.26731 | O19: 114.36133 | P19: 115.53986 | Q19: 116.6934 | R19: 117.93478 | S19: 119.26325 | T19: 120.51714 | U19: 121.9657 | V19: 123.54321 | W19: 125.05544 | X19: 126.4902 | Y19: 127.8319 | Z19: 129.14803 | AA19: 130.64792 | AB19: 132.25534 | AC19: 133.71924 | AD19: 135.16911 | AE19: 137.06503 | AF19: 0.010533
A20: TKI000:ba_FreightTrucks | B20: Freight Trucks greater than 10,000 pounds | C20: 321.95499 | D20: 320.72061 | E20: 321.15665 | F20: 324.03918 | G20: 328.45148 | H20: 332.31928 | I20: 335.87875 | J20: 338.621 | K20: 341.15326 | L20: 344.16229 | M20: 348.16583 | N20: 351.54123 | O20: 354.83011 | P20: 358.3447 | Q20: 361.39355 | R20: 364.92679 | S20: 368.38065 | T20: 371.81143 | U20: 375.58807 | V20: 379.58752 | W20: 383.51465 | X20: 387.20883 | Y20: 390.63339 | Z20: 393.83795 | AA20: 397.54263 | AB20: 401.35467 | AC20: 404.65982 | AD20: 408.22446 | AE20: 413.08252 | AF20: 0.008941
B21: (billion passenger miles traveled)
A22: TKI000:buspassmiles | B22: Bus Transportation | C22: 175.47365 | D22: 186.88329 | E22: 193.3692 | F22: 197.39229 | G22: 200.32752 | H22: 202.52968 | I22: 204.21141 | J22: 205.46838 | K22: 206.39357 | L22: 207.0294 | M22: 207.54085 | N22: 207.99565 | O22: 208.43976 | P22: 208.79684 | Q22: 209.10339 | R22: 209.37013 | S22: 209.49379 | T22: 209.54416 | U22: 209.54358 | V22: 209.49118 | W22: 209.41185 | X22: 209.25844 | Y22: 209.10913 | Z22: 208.93102 | AA22: 208.81189 | AB22: 208.60612 | AC22: 208.41769 | AD22: 208.19235 | AE22: 207.99593 | AF22: 0.006091
A23: TKI000:railpassmiles | B23: Passenger Rail | C23: 30.144947 | D23: 32.030231 | E23: 33.06411 | F23: 33.706196 | G23: 34.620327 | H23: 35.443916 | I23: 36.137474 | J23: 36.650322 | K23: 37.00806 | L23: 37.264553 | M23: 37.633518 | N23: 38.06789 | O23: 38.564194 | P23: 38.985653 | Q23: 39.398945 | R23: 39.809189 | S23: 40.237045 | T23: 40.652229 | U23: 41.127975 | V23: 41.567631 | W23: 42.019573 | X23: 42.40731 | Y23: 42.842342 | Z23: 43.266335 | AA23: 43.867863 | AB23: 44.361511 | AC23: 44.905075 | AD23: 45.395485 | AE23: 46.002594 | AF23: 0.01521
B24: (billion seat miles available)
A25: TKI000:ba_Air | B25: Air | C25: 1173.0347 | D25: 1318.6946 | E25: 1361.6111 | F25: 1371.6552 | G25: 1402.928 | H25: 1433.8398 | I25: 1461.4722 | J25: 1484.8291 | K25: 1504.2688 | L25: 1524.7269 | M25: 1552.2568 | N25: 1583.9248 | O25: 1615.3802 | P25: 1647.3462 | Q25: 1682.5896 | R25: 1721.0469 | S25: 1761.139 | T25: 1801.941 | U25: 1848.072 | V25: 1894.2041 | W25: 1941.463 | X25: 1990.3643 | Y25: 2038.4374 | Z25: 2085.6875 | AA25: 2134.0049 | AB25: 2185.897 | AC25: 2238.8362 | AD25: 2292.3555 | AE25: 2350.269 | AF25: 0.02513
B26: (billion ton miles traveled)
A27: TKI000:ba_Rail | B27: Rail | C27: 1620.4949 | D27: 1600.1008 | E27: 1666.9198 | F27: 1628.4084 | G27: 1561.4207 | H27: 1509.6494 | I27: 1489.7312 | J27: 1507.5151 | K27: 1500.1649 | L27: 1506.9524 | M27: 1522.1982 | N27: 1534.7394 | O27: 1543.2374 | P27: 1554.5907 | Q27: 1557.5254 | R27: 1562.4816 | S27: 1568.9661 | T27: 1568.3395 | U27: 1571.7775 | V27: 1585.6112 | W27: 1597.307 | X27: 1600.1909 | Y27: 1601.8328 | Z27: 1602.9988 | AA27: 1608.1294 | AB27: 1618.0824 | AC27: 1630.808 | AD27: 1636.8905 | AE27: 1649.4695 | AF27: 0.000633
A28: TKI000:ba_DomesticShipp | B28: Domestic Shipping | C28: 444.89887 | D28: 450.42761 | E28: 448.61005 | F28: 446.74628 | G28: 445.22772 | H28: 442.84778 | I28: 440.43005 | J28: 437.0246 | K28: 434.03641 | L28: 431.39212 | M28: 429.99737 | N28: 428.16068 | O28: 426.27862 | P28: 424.17816 | Q28: 421.71698 | R28: 419.81464 | S28: 417.56705 | T28: 415.80768 | U28: 414.04514 | V28: 412.52209 | W28: 411.24774 | X28: 409.97736 | Y28: 408.52225 | Z28: 406.63034 | AA28: 405.35852 | AB28: 403.86591 | AC28: 401.97906 | AD28: 400.55664 | AE28: 400.09833 | AF28: -0.003783
B30: Energy Efficiency Indicators | C30: =C41/C38 -> 0.81570903 | D30: =C30/'EPA Auto Trends 2022'!B3 -> 1.0579946
B31: (miles per gallon)
A32: TKI000:ca_AvgCAFEStand | B32: New Light-Duty Vehicle CAFE Standard 2/ | C32: 35.855949 | D32: 36.277985 | E32: 39.337013 | F32: 42.578201 | G32: 47.262627 | H32: 47.227249 | I32: 47.18121 | J32: 47.168774 | K32: 47.163849 | L32: 47.152081 | M32: 47.159279 | N32: 47.152672 | O32: 47.146118 | P32: 47.131687 | Q32: 47.138325 | R32: 47.119869 | S32: 47.100937 | T32: 47.084251 | U32: 47.059879 | V32: 47.032314 | W32: 47.004074 | X32: 46.960155 | Y32: 46.939564 | Z32: 46.91069 | AA32: 46.948238 | AB32: 46.913113 | AC32: 46.90683 | AD32: 46.880138 | AE32: 46.870857 | AF32: 0.009613
A33: TKI000:ca_CarCAFEStand | B33: New Car 2/ | C33: 45.004654 | D33: 45.471119 | E33: 49.460312 | F33: 53.789036 | G33: 59.791531 | H33: 59.80352 | I33: 59.817413 | J33: 59.819332 | K33: 59.821598 | L33: 59.822445 | M33: 59.827473 | N33: 59.828793 | O33: 59.83078 | P33: 59.83112 | Q33: 59.842136 | R33: 59.842136 | S33: 59.842136 | T33: 59.843197 | U33: 59.843197 | V33: 59.843231 | W33: 59.845177 | X33: 59.845177 | Y33: 59.848228 | Z33: 59.848228 | AA33: 59.867775 | AB33: 59.867775 | AC33: 59.867775 | AD33: 59.867775 | AE33: 59.867775 | AF33: 0.010244
A34: TKI000:ca_TwukCAFEStand | B34: New Light Truck 2/ | C34: 32.047302 | D34: 32.608868 | E34: 35.403008 | F34: 38.46349 | G34: 42.755749 | H34: 42.75658 | I34: 42.76173 | J34: 42.76173 | K34: 42.761841 | L34: 42.762085 | M34: 42.762169 | N34: 42.76236 | O34: 42.76239 | P34: 42.76252 | Q34: 42.762554 | R34: 42.762699 | S34: 42.762756 | T34: 42.762825 | U34: 42.762897 | V34: 42.762962 | W34: 42.763016 | X34: 42.763103 | Y34: 42.763103 | Z34: 42.763184 | AA34: 42.763184 | AB34: 42.763294 | AC34: 42.763294 | AD34: 42.763393 | AE34: 42.763393 | AF34: 0.010356
A35: TKI000:ca_NewVehCred | B35: Compliance New Light-Duty Vehicle 3/ | C35: 41.802036 | D35: 43.2672 | E35: 44.448151 | F35: 47.052715 | G35: 48.571758 | H35: 49.79253 | I35: 52.281479 | J35: 53.248959 | K35: 53.962006 | L35: 54.332035 | M35: 54.872646 | N35: 55.329353 | O35: 55.771633 | P35: 56.242725 | Q35: 56.632603 | R35: 56.856194 | S35: 57.030457 | T35: 57.310715 | U35: 57.240421 | V35: 57.306023 | W35: 57.371868 | X35: 57.326744 | Y35: 57.237999 | Z35: 57.125122 | AA35: 57.475964 | AB35: 57.327747 | AC35: 57.273457 | AD35: 57.524818 | AE35: 57.479156 | AF35: 0.011439
A36: TKI000:ca_NewCarCred | B36: New Car 3/ | C36: 56.582645 | D36: 58.322227 | E36: 59.783314 | F36: 64.222374 | G36: 65.997482 | H36: 68.148636 | I36: 72.759445 | J36: 74.876167 | K36: 76.446304 | L36: 77.157303 | M36: 78.145363 | N36: 78.735664 | O36: 79.269257 | P36: 79.864815 | Q36: 80.311752 | R36: 80.510567 | S36: 80.643074 | T36: 81.042244 | U36: 80.790894 | V36: 80.999863 | W36: 81.213394 | X36: 81.251564 | Y36: 81.126785 | Z36: 80.963654 | AA36: 81.962257 | AB36: 81.685669 | AC36: 81.57402 | AD36: 82.338425 | AE36: 82.243484 | AF36: 0.013446
A37: TKI000:ca_NewTwukCred | B37: New Light Truck 3/ | C37: 36.263931 | D37: 37.832123 | E37: 39.014805 | F37: 41.375153 | G37: 42.876762 | H37: 43.911583 | I37: 45.953789 | J37: 46.678478 | K37: 47.207012 | L37: 47.518375 | M37: 47.939487 | N37: 48.362621 | O37: 48.779861 | P37: 49.233047 | Q37: 49.585567 | R37: 49.838345 | S37: 50.048077 | T37: 50.325745 | U37: 50.338009 | V37: 50.426777 | W37: 50.517311 | X37: 50.542614 | Y37: 50.50412 | Z37: 50.459385 | AA37: 50.61805 | AB37: 50.565735 | AC37: 50.535652 | AD37: 50.739391 | AE37: 50.721836 | AF37: 0.012055
A38: TKI000:ca_TestedNewVeh | B38: Tested New Light-Duty Vehicle 4/ | C38: 37.621078 | D38: 38.382416 | E38: 39.075672 | F38: 40.794502 | G38: 41.684994 | H38: 42.387779 | I38: 43.992405 | J38: 44.482399 | K38: 44.828846 | L38: 45.012852 | M38: 45.295109 | N38: 45.54966 | O38: 45.800465 | P38: 46.072914 | Q38: 46.308186 | R38: 46.454895 | S38: 46.573441 | T38: 46.763412 | U38: 46.743324 | V38: 46.781216 | W38: 46.812752 | X38: 46.781078 | Y38: 46.720787 | Z38: 46.649311 | AA38: 46.812588 | AB38: 46.721981 | AC38: 46.686661 | AD38: 46.844208 | AE38: 46.809135 | AF38: 0.007835
A39: TKI000:ca_TestedNewCar | B39: New Car 4/ | C39: 49.658657 | D39: 50.63982 | E39: 51.418789 | F39: 54.041267 | G39: 54.808311 | H39: 55.812794 | I39: 58.414131 | J39: 59.295654 | K39: 59.885937 | L39: 60.128426 | M39: 60.482559 | N39: 60.696911 | O39: 60.896141 | P39: 61.139969 | Q39: 61.34211 | R39: 61.456459 | S39: 61.54549 | T39: 61.791069 | U39: 61.720493 | V39: 61.820892 | W39: 61.909645 | X39: 61.923454 | Y39: 61.848679 | Z39: 61.762375 | AA39: 62.120819 | AB39: 61.989952 | AC39: 61.932671 | AD39: 62.331699 | AE39: 62.272804 | AF39: 0.008117
A40: TKI000:ca_TestedNewTwuk | B40: New Light Truck 4/ | C40: 32.951321 | D40: 33.82571 | E40: 34.570251 | F40: 36.235542 | G40: 37.203815 | H40: 37.859802 | I40: 39.251301 | J40: 39.65464 | K40: 39.942871 | L40: 40.123779 | M40: 40.372108 | N40: 40.635685 | O40: 40.898228 | P40: 41.187042 | Q40: 41.415565 | R40: 41.589336 | S40: 41.735809 | T40: 41.930031 | U40: 41.954327 | V40: 42.014381 | W40: 42.070942 | X40: 42.089371 | Y40: 42.062252 | Z40: 42.034523 | AA40: 42.106945 | AB40: 42.074627 | AC40: 42.053329 | AD40: 42.192116 | AE40: 42.17543 | AF40: 0.008853
A41: TKI000:ca_OnRoadNewVeh | B41: On-Road New Light-Duty Vehicle 5/ | C41: 30.687853 | D41: 31.308468 | E41: 31.873775 | F41: 33.275242 | G41: 34.001518 | H41: 34.574638 | I41: 35.883228 | J41: 36.28281 | K41: 36.56535 | L41: 36.715401 | M41: 36.945652 | N41: 37.153278 | O41: 37.357868 | P41: 37.580082 | Q41: 37.772026 | R41: 37.891651 | S41: 37.988308 | T41: 38.143211 | U41: 38.126759 | V41: 38.157574 | W41: 38.183201 | X41: 38.157219 | Y41: 38.107975 | Z41: 38.049587 | AA41: 38.182838 | AB41: 38.108822 | AC41: 38.080002 | AD41: 38.208389 | AE41: 38.179749 | AF41: 0.007832
A42: TKI000:ca_OnRoadNewCar | B42: New Car 5/ | C42: 40.552002 | D42: 41.353237 | E42: 41.989353 | F42: 44.130909 | G42: 44.75729 | H42: 45.577564 | I42: 47.701855 | J42: 48.421719 | K42: 48.903755 | L42: 49.101772 | M42: 49.390965 | N42: 49.566006 | O42: 49.728703 | P42: 49.927814 | Q42: 50.092888 | R42: 50.186264 | S42: 50.258968 | T42: 50.459515 | U42: 50.401878 | V42: 50.483868 | W42: 50.556343 | X42: 50.567619 | Y42: 50.506557 | Z42: 50.436081 | AA42: 50.72879 | AB42: 50.621925 | AC42: 50.575146 | AD42: 50.901001 | AE42: 50.852905 | AF42: 0.008117
A43: TKI000:ca_OnRoadNewTwuk | B43: New Light Truck 5/ | C43: 26.867123 | D43: 27.580063 | E43: 28.18713 | F43: 29.544939 | G43: 30.334429 | H43: 30.869291 | I43: 32.00386 | J43: 32.332729 | K43: 32.567738 | L43: 32.715244 | M43: 32.917721 | N43: 33.132629 | O43: 33.346695 | P43: 33.582184 | Q43: 33.768513 | R43: 33.910198 | S43: 34.029625 | T43: 34.187984 | U43: 34.207794 | V43: 34.25676 | W43: 34.302879 | X43: 34.317905 | Y43: 34.295792 | Z43: 34.273186 | AA43: 34.332233 | AB43: 34.305882 | AC43: 34.288517 | AD43: 34.40168 | AE43: 34.388073 | AF43: 0.008853
... A47: TKI000:ca_FreightTruck | B47: Freight Truck | C47: 7.472406 | D47: 7.578529 | E47: 7.705323 | F47: 7.84859 | G47: 8.002383 | H47: 8.163677 | I47: 8.321285 | J47: 8.479755 | K47: 8.638294 | L47: 8.79593 | M47: 8.948549 | N47: 9.090997 | O47: 9.222516 | P47: 9.343068 | Q47: 9.453315 | R47: 9.553063 | S47: 9.643444 | T47: 9.72671 | U47: 9.804593 | V47: 9.877275 | W47: 9.942431 | X47: 10.001567 | Y47: 10.055841 | Z47: 10.108454 | AA47: 10.161228 | AB47: 10.213311 | AC47: 10.263764 | AD47: 10.314513 | AE47: 10.365861 | AF47: 0.011758
B48: (seat miles per gallon)
A49: TKI000:ca_Aircraft | B49: Aircraft | C49: 72.717087 | D49: 73.091972 | E49: 73.492531 | F49: 74.018456 | G49: 74.683121 | H49: 75.131767 | I49: 75.59214 | J49: 76.024017 | K49: 76.492363 | L49: 77.014214 | M49: 77.60096 | N49: 78.266678 | O49: 78.981506 | P49: 79.730591 | Q49: 80.48922 | R49: 81.260979 | S49: 82.048454 | T49: 82.814575 | U49: 83.594772 | V49: 84.382309 | W49: 85.171204 | X49: 85.974022 | Y49: 86.764038 | Z49: 87.549927 | AA49: 88.321091 | AB49: 89.091156 | AC49: 89.849762 | AD49: 90.593376 | AE49: 91.328148 | AF49: 0.008172
...

Sheet AEO 2025 Table 7
A1: Table 7. Transportation Sector Key Indicators and Delivered Energy Consumption
A2: https://www.eia.gov/outlooks/aeo/data/browser/#/?id=7-AEO2025&cases=alttrnp&sourcekey=0
A3: Fri Dec 05 2025 14:42:41 GMT-0800 (Pacific Standard Time)
A4: Source: U.S. Energy Information Administration
B5: full name | C5: api key | D5: units | E5: 2023 | F5: 2024 | G5: 2025 | H5: 2026 | I5: 2027 | J5: 2028 | K5: 2029 | L5: 2030 | M5: 2031 | N5: 2032 | O5: 2033 | P5: 2034 | Q5: 2035 | R5: 2036 | S5: 2037 | T5: 2038 | U5: 2039 | V5: 2040 | W5: 2041 | X5: 2042 | Y5: 2043 | Z5: 2044 | AA5: 2045 | AB5: 2046 | AC5: 2047 | AD5: 2048 | AE5: 2049 | AF5: 2050 | AG5: Growth (2024-2050)
A6: Key Indicators
A7: Travel Indicators
A8: (billion vehicle miles traveled)
A9: Light-Duty Vehicles less than 8 | B9: Transportation: Travel Indicators: Light-Duty Vehicles <= 8,500 lbs: Alternative Transportation | C9: AEO.2025.ALTTRNP.KEI_TRV_TRN_NA_LDV_NA_NA_BLNVEHMLS.A | D9: billion vehicle miles | F9: 3013.7297 | G9: 3058.3716 | H9: 3083.4512 | I9: 3100.0171 | J9: 3112.2297 | K9: 3125.5762 | L9: 3140.167 | M9: 3154.0073 | N9: 3161.4351 | O9: 3167.1465 | P9: 3171.917 | Q9: 3174.3567 | R9: 3179.4163 | S9: 3189.5078 | T9: 3202.9607 | U9: 3216.1187 | V9: 3230.5129 | W9: 3244.2317 | X9: 3257.2742 | Y9: 3268.8367 | Z9: 3279.3418 | AA9: 3288.4412 | AB9: 3297.5173 | AC9: 3308.5703 | AD9: 3321.3464 | AE9: 3335.0469 | AF9: 3349.864 | AG9: 0.004
A10: Commercial Light Trucks | B10: Transportation: Travel Indicators: Commercial Light Trucks: Alternative Transportation | C10: AEO.2025.ALTTRNP.KEI_TRV_TRN_NA_CML_NA_NA_BLNVEHMLS.A | D10: billion vehicle miles | F10: 90.234665 | G10: 88.746048 | H10: 87.524918 | I10: 86.879402 | J10: 86.146126 | K10: 85.551414 | L10: 85.088478 | M10: 84.55584 | N10: 84.013214 | O10: 83.542664 | P10: 83.043007 | Q10: 82.538109 | R10: 82.013916 | S10: 81.499672 | T10: 80.976738 | U10: 80.459801 | V10: 79.954575 | W10: 79.410118 | X10: 78.884186 | Y10: 78.326515 | Z10: 77.80687 | AA10: 77.239433 | AB10: 76.680191 | AC10: 76.081207 | AD10: 75.451775 | AE10: 74.792137 | AF10: 74.117767 | AG10: -0.008
A11: Freight Trucks greater than 10 | B11: Transportation: Travel Indicators: Freight Trucks > 10,000 lbs.: Alternative Transportation | C11: AEO.2025.ALTTRNP.KEI_TRV_TRN_NA_FGHT_NA_NA_BLNVEHMLS.A | D11: billion vehicle miles | F11: 340.05481 | G11: 346.20789 | H11: 350.06781 | I11: 353.52682 | J11: 356.01294 | K11: 358.95523 | L11: 362.11615 | M11: 364.84686 | N11: 367.715 | O11: 370.28033 | P11: 373.22687 | Q11: 376.19421 | R11: 379.62561 | S11: 383.28888 | T11: 386.97992 | U11: 390.32495 | V11: 393.89111 | W11: 397.25488 | X11: 400.59506 | Y11: 403.50134 | Z11: 406.14972 | AA11: 409.08057 | AB11: 411.83875 | AC11: 416.01117 | AD11: 420.09766 | AE11: 423.84226 | AF11: 427.05206 | AG11: 0.009
A12: (billion passenger miles traveled)
A13: Bus Transportation | B13: Transportation: Travel Indicators: Bus: Alternative Transportation | C13: AEO.2025.ALTTRNP.KEI_TRV_TRN_NA_BST_NA_NA_BPM.A | D13: billion passenger miles | F13: 190.78021 | G13: 196.63762 | H13: 200.38203 | I13: 202.76497 | J13: 204.50441 | K13: 205.76622 | L13: 206.65466 | M13: 207.15369 | N13: 207.40228 | O13: 207.54491 | P13: 207.69394 | Q13: 207.71609 | R13: 207.67081 | S13: 207.61053 | T13: 207.42905 | U13: 207.19026 | V13: 206.88676 | W13: 206.52594 | X13: 206.10233 | Y13: 205.65778 | Z13: 205.15973 | AA13: 204.65633 | AB13: 204.09099 | AC13: 203.49281 | AD13: 202.89883 | AE13: 202.30595 | AF13: 201.76945 | AG13: 0.002
A14: Passenger Rail | B14: Transportation: Travel Indicators: Passenger Rail: Alternative Transportation | C14: AEO.2025.ALTTRNP.KEI_TRV_TRN_NA_RLP_NA_NA_BPM.A | D14: billion passenger miles | F14: 25.878023 | G14: 28.773293 | H14: 30.990028 | I14: 32.691128 | J14: 34.018692 | K14: 35.161125 | L14: 36.109001 | M14: 36.852859 | N14: 37.463329 | O14: 37.9645 | P14: 38.458427 | Q14: 38.854378 | R14: 39.233795 | S14: 39.64349 | T14: 40.072304 | U14: 40.454437 | V14: 40.811695 | W14: 41.128437 | X14: 41.427906 | Y14: 41.717632 | Z14: 41.951229 | AA14: 42.199917 | AB14: 42.38929 | AC14: 42.61396 | AD14: 42.893345 | AE14: 43.173431 | AF14: 43.548084 | AG14: 0.02
A15: (billion seat miles available)
A16: Air | B16: Transportation: Travel Indicators: Air: Alternative Transportation | C16: AEO.2025.ALTTRNP.KEI_TRV_TRN_NA_AIR_NA_NA_BLNSEATMLS.A | D16: billion seat miles | F16: 1413.1366 | G16: 1426.5015 | H16: 1461.8976 | I16: 1494.7886 | J16: 1522.1002 | K16: 1551.6201 | L16: 1578.683 | M16: 1601.1815 | N16: 1627.1464 | O16: 1654.8922 | P16: 1681.6215 | Q16: 1711.0176 | R16: 1740.9607 | S16: 1772.7719 | T16: 1806.9364 | U16: 1841.1686 | V16: 1875.4396 | W16: 1909.1254 | X16: 1945.6185 | Y16: 1981.347 | Z16: 2014.7141 | AA16: 2047.4543 | AB16: 2079.6472 | AC16: 2117.3379 | AD16: 2157.5337 | AE16: 2196.0696 | AF16: 2234.0925 | AG16: 0.018
A17: (billion ton miles traveled)
A18: Rail | B18: Transportation: Travel Indicators: Rail: Alternative Transportation | C18: AEO.2025.ALTTRNP.KEI_TRV_TRN_NA_RAIL_NA_NA_BLNTNMLS.A | D18: billion ton miles | F18: 1464.8552 | G18: 1498.5776 | H18: 1462.3732 | I18: 1413.7332 | J18: 1414.1151 | K18: 1410.5652 | L18: 1369.7415 | M18: 1370.1805 | N18: 1305.8112 | O18: 1312.2113 | P18: 1299.8524 | Q18: 1300.421 | R18: 1305.7511 | S18: 1312.3923 | T18: 1330.2866 | U18: 1321.975 | V18: 1328.3295 | W18: 1330.2947 | X18: 1337.3475 | Y18: 1345.2047 | Z18: 1349.7686 | AA18: 1354.5587 | AB18: 1355.686 | AC18: 1370.3556 | AD18: 1382.5275 | AE18: 1392.7019 | AF18: 1397.2123 | AG18: -0.002
A19: Domestic Shipping | B19: Transportation: Travel Indicators: Domestic Shipping: Alternative Transportation | C19: AEO.2025.ALTTRNP.KEI_TRV_TRN_NA_DMT_NA_NA_BLNTNMLS.A | D19: billion ton miles | F19: 458.77335 | G19: 464.89285 | H19: 462.96167 | I19: 460.98572 | J19: 459.37042 | K19: 457.35059 | L19: 454.85974 | M19: 451.94983 | N19: 448.2905 | O19: 446.2366 | P19: 444.57028 | Q19: 442.67673 | R19: 440.63129 | S19: 439.09964 | T19: 437.71414 | U19: 435.98474 | V19: 434.76898 | W19: 433.49097 | X19: 432.2272 | Y19: 430.6734 | Z19: 428.80133 | AA19: 427.06717 | AB19: 425.276 | AC19: 424.65442 | AD19: 423.51385 | AE19: 422.14224 | AF19: 420.62109 | AG19: -0.003
A20: Energy Efficiency Indicators
A21: (miles per gallon)
A22: New Light-Duty Vehicle CAFE Standard | B22: Transportation: Energy Efficiency Indicators: CAFE Standard: New Light-Duty Vehicle: Alternative Transportation | C22: AEO.2025.ALTTRNP.EFI_CAFES_TRN_HWY_LDTY_NEW_NA_MLSPGLN.A | D22: mpg | F22: 39.271114 | G22: 42.959927 | H22: 47.575771 | I22: 47.493256 | J22: 47.449085 | K22: 47.490925 | L22: 47.59132 | M22: 47.604393 | N22: 47.569965 | O22: 47.492599 | P22: 47.679401 | Q22: 47.648468 | R22: 47.59169 | S22: 47.590065 | T22: 47.59457 | U22: 47.597126 | V22: 47.557652 | W22: 47.536556 | X22: 47.522251 | Y22: 47.527641 | Z22: 47.509605 | AA22: 47.515839 | AB22: 47.499699 | AC22: 47.476486 | AD22: 47.471779 | AE22: 47.466419 | AF22: 47.51144 | AG22: 0.007
A23: New Car | B23: Transportation: Energy Efficiency Indicators: CAFE Standard: New Car: Alternative Transportation | C23: AEO.2025.ALTTRNP.EFI_CAFES_TRN_HWY_CAR_NEW_NA_MLSPGLN.A | D23: mpg | F23: 48.175083 | G23: 52.414536 | H23: 58.241451 | I23: 58.255463 | J23: 58.26667 | K23: 58.284412 | L23: 58.290977 | M23: 58.296238 | N23: 58.292618 | O23: 58.297882 | P23: 58.32222 | Q23: 58.317551 | R23: 58.313091 | S23: 58.312267 | T23: 58.318325 | U23: 58.320648 | V23: 58.313702 | W23: 58.314289 | X23: 58.312122 | Y23: 58.322739 | Z23: 58.317924 | AA23: 58.327766 | AB23: 58.321186 | AC23: 58.318832 | AD23: 58.325527 | AE23: 58.327377 | AF23: 58.347694 | AG23: 0.007
A24: New Light Truck | B24: Transportation: Energy Efficiency Indicators: CAFE Standard: New Light Truck: Alternative Transportation | C24: AEO.2025.ALTTRNP.EFI_CAFES_TRN_HWY_LTRT_NEW_NA_MLSPGLN.A | D24: mpg | F24: 35.086903 | G24: 38.087925 | H24: 42.293404 | I24: 42.265976 | J24: 42.251019 | K24: 42.23045 | L24: 42.21875 | M24: 42.207088 | N24: 42.198193 | O24: 42.188656 | P24: 42.178352 | Q24: 42.170338 | R24: 42.163197 | S24: 42.15712 | T24: 42.150414 | U24: 42.144039 | V24: 42.139084 | W24: 42.13335 | X24: 42.127731 | Y24: 42.121071 | Z24: 42.115974 | AA24: 42.109615 | AB24: 42.105438 | AC24: 42.100983 | AD24: 42.095028 | AE24: 42.089645 | AF24: 42.083157 | AG24: 0.007
A25: Compliance New Light-Duty Vehicle | B25: Transportation: Energy Efficiency Indicators: Compliance: New Light-Duty Vehicle: Alternative Transportation | C25: AEO.2025.ALTTRNP.EFI_CAFEC_TRN_HWY_LDTY_NEW_NA_MLSPGLN.A | D25: mpg | F25: 39.942822 | G25: 43.957706 | H25: 47.924385 | I25: 48.168633 | J25: 48.206814 | K25: 47.845936 | L25: 47.905159 | M25: 48.590633 | N25: 49.493092 | O25: 48.658333 | P25: 49.540321 | Q25: 50.266624 | R25: 50.779812 | S25: 51.219345 | T25: 51.674301 | U25: 52.231579 | V25: 52.558426 | W25: 52.808189 | X25: 52.984974 | Y25: 53.223259 | Z25: 53.34993 | AA25: 53.548645 | AB25: 53.65453 | AC25: 53.715496 | AD25: 53.847446 | AE25: 53.972466 | AF25: 54.298809 | AG25: 0.012
A26: New Car | B26: Transportation: Energy Efficiency Indicators: Compliance: New Car: Alternative Transportation | C26: AEO.2025.ALTTRNP.EFI_CAFEC_TRN_HWY_CAR_NEW_NA_MLSPGLN.A | D26: mpg | F26: 53.113453 | G26: 57.640594 | H26: 63.3256 | I26: 68.261688 | J26: 68.800171 | K26: 66.58007 | L26: 66.17157 | M26: 67.334129 | N26: 70.141273 | O26: 69.02169 | P26: 70.175095 | Q26: 72.345963 | R26: 73.417397 | S26: 74.362701 | T26: 75.273003 | U26: 76.767471 | V26: 77.966553 | W26: 78.546875 | X26: 79.005653 | Y26: 79.448586 | Z26: 79.81424 | AA26: 80.153214 | AB26: 80.456696 | AC26: 80.688454 | AD26: 80.951462 | AE26: 81.205383 | AF26: 81.537048 | AG26: 0.017
A27: New Light Truck | B27: Transportation: Energy Efficiency Indicators: Compliance: New Light Truck: Alternative Transportation | C27: AEO.2025.ALTTRNP.EFI_CAFEC_TRN_HWY_LTRT_NEW_NA_MLSPGLN.A | D27: mpg | F27: 34.459515 | G27: 37.642277 | H27: 41.127472 | I27: 40.267258 | J27: 40.25531 | K27: 40.242519 | L27: 40.218754 | M27: 40.700054 | N27: 41.130524 | O27: 40.5546 | P27: 40.930511 | Q27: 41.310795 | R27: 41.765965 | S27: 42.053349 | T27: 42.351562 | U27: 42.643215 | V27: 42.837719 | W27: 43.033184 | X27: 43.158432 | Y27: 43.308086 | Z27: 43.407925 | AA27: 43.533504 | AB27: 43.621685 | AC27: 43.68882 | AD27: 43.782269 | AE27: 43.872547 | AF27: 44.049908 | AG27: 0.009
A28: Tested New Light-Duty Vehicle | B28: Transportation: Energy Efficiency Indicators: Tested: New Light-Duty Vehicle: Alternative Transportation | C28: AEO.2025.ALTTRNP.EFI_CAFET_TRN_HWY_LDTY_NEW_NA_MLSPGLN.A | D28: mpg | F28: 36.992214 | G28: 40.049953 | H28: 42.808971 | I28: 43.230892 | J28: 44.016903 | K28: 44.308899 | L28: 44.989899 | M28: 45.61496 | N28: 46.454155 | O28: 45.667557 | P28: 46.478081 | Q28: 47.149429 | R28: 47.616024 | S28: 48.020485 | T28: 48.435196 | U28: 48.949013 | V28: 49.253231 | W28: 49.479267 | X28: 49.642773 | Y28: 49.856163 | Z28: 49.976059 | AA28: 50.153816 | AB28: 50.256393 | AC28: 50.313774 | AD28: 50.431538 | AE28: 50.545406 | AF28: 50.836014 | AG28: 0.012
A29: New Car | B29: Transportation: Energy Efficiency Indicators: Tested: New Car: Alternative Transportation | C29: AEO.2025.ALTTRNP.EFI_CAFET_TRN_HWY_CAR_NEW_NA_MLSPGLN.A | D29: mpg | F29: 48.381924 | G29: 51.754009 | H29: 55.653797 | I29: 59.137737 | J29: 61.278339 | K29: 61.308632 | L29: 62.88327 | M29: 63.968285 | N29: 66.642883 | O29: 65.576897 | P29: 66.66021 | Q29: 68.722473 | R29: 69.727547 | S29: 70.61306 | T29: 71.466324 | U29: 72.886696 | V29: 74.021286 | W29: 74.5662 | X29: 74.998436 | Y29: 75.41684 | Z29: 75.761993 | AA29: 76.083054 | AB29: 76.370346 | AC29: 76.590515 | AD29: 76.839706 | AE29: 77.080559 | AF29: 77.395805 | AG29: 0.018
A30: New Light Truck | B30: Transportation: Energy Efficiency Indicators: Tested: New Light Truck: Alternative Transportation | C30: AEO.2025.ALTTRNP.EFI_CAFET_TRN_HWY_LTRT_NEW_NA_MLSPGLN.A | D30: mpg | F30: 32.114288 | G30: 34.514839 | H30: 36.986862 | I30: 36.634201 | J30: 37.092926 | K30: 37.343777 | L30: 37.577011 | M30: 38.011017 | N30: 38.403038 | O30: 37.869068 | P30: 38.209908 | Q30: 38.555424 | R30: 38.963661 | S30: 39.224598 | T30: 39.495064 | U30: 39.75996 | V30: 39.93721 | W30: 40.114799 | X30: 40.230305 | Y30: 40.36813 | Z30: 40.460381 | AA30: 40.576187 | AB30: 40.657494 | AC30: 40.719509 | AD30: 40.805653 | AE30: 40.888672 | AF30: 41.051575 | AG30: 0.009
A31: On-Road New Light-Duty Vehicle | B31: Transportation: Energy Efficiency Indicators: On-Road New Light-Duty Vehicle: Alternative Transportation | C31: AEO.2025.ALTTRNP.EFI_CAFEO_TRN_HWY_LDTY_NEW_NA_MLSPGLN.A | D31: mpg | F31: 27.538565 | G31: 29.747971 | H31: 31.720669 | I31: 32.058968 | J31: 32.641983 | K31: 32.859589 | L31: 33.335556 | M31: 33.78616 | N31: 34.398438 | O31: 33.841164 | P31: 34.423504 | Q31: 34.90659 | R31: 35.2328 | S31: 35.521309 | T31: 35.816288 | U31: 36.185467 | V31: 36.402821 | W31: 36.561584 | X31: 36.675686 | Y31: 36.824799 | Z31: 36.907936 | AA31: 37.031731 | AB31: 37.102467 | AC31: 37.140446 | AD31: 37.221237 | AE31: 37.299519 | AF31: 37.503345 | AG31: 0.012
A32: New Car | B32: Transportation: Energy Efficiency Indicators: On-Road New Car: Alternative Transportation | C32: AEO.2025.ALTTRNP.EFI_CAFEO_TRN_HWY_CAR_NEW_NA_MLSPGLN.A | D32: mpg | F32: 35.736515 | G32: 38.187515 | H32: 41.026562 | I32: 43.567795 | J32: 45.12907 | K32: 45.143227 | L32: 46.28548 | M32: 47.069462 | N32: 49.029163 | O32: 48.263416 | P32: 49.0424 | Q32: 50.544037 | R32: 51.270535 | S32: 51.909389 | T32: 52.522804 | U32: 53.556107 | V32: 54.379284 | W32: 54.76899 | X32: 55.077839 | Y32: 55.373089 | Z32: 55.619442 | AA32: 55.844055 | AB32: 56.048706 | AC32: 56.203579 | AD32: 56.377033 | AE32: 56.545631 | AF32: 56.762432 | AG32: 0.018
A33: New Light Truck | B33: Transportation: Energy Efficiency Indicators: On-Road New Light Truck: Alternative Transportation | C33: AEO.2025.ALTTRNP.EFI_CAFEO_TRN_HWY_LTRT_NEW_NA_MLSPGLN.A | D33: mpg | F33: 23.988018 | G33: 25.717506 | H33: 27.470898 | I33: 27.24152 | J33: 27.584202 | K33: 27.775764 | L33: 27.919968 | M33: 28.231255 | N33: 28.51063 | O33: 28.137867 | P33: 28.37771 | Q33: 28.619431 | R33: 28.901937 | S33: 29.085546 | T33: 29.275507 | U33: 29.461161 | V33: 29.584818 | W33: 29.708748 | X33: 29.788166 | Y33: 29.883118 | Z33: 29.9464 | AA33: 30.026072 | AB33: 30.081591 | AC33: 30.123497 | AD33: 30.182156 | AE33: 30.238665 | AF33: 30.351025 | AG33: 0.009
... A37: Freight Truck | B37: Transportation: Energy Efficiency Indicators: Freight Truck: Alternative Transportation | C37: AEO.2025.ALTTRNP.EFI_NA_TRN_HWY_FRTT_STK_NA_MLSPGLN.A | D37: mpg | F37: 7.757023 | G37: 7.826031 | H37: 7.906292 | I37: 7.996029 | J37: 8.094789 | K37: 8.199175 | L37: 8.307471 | M37: 8.417607 | N37: 8.528322 | O37: 8.63801 | P37: 8.745068 | Q37: 8.847067 | R37: 8.942054 | S37: 9.029954 | T37: 9.112733 | U37: 9.191482 | V37: 9.266891 | W37: 9.337207 | X37: 9.402058 | Y37: 9.46137 | Z37: 9.51621 | AA37: 9.569106 | AB37: 9.620891 | AC37: 9.670567 | AD37: 9.716979 | AE37: 9.761371 | AF37: 9.804544 | AG37: 0.009
A38: (seat miles per gallon)
A39: Aircraft | B39: Transportation: Energy Efficiency Indicators: Aircraft: Alternative Transportation | C39: AEO.2025.ALTTRNP.EFI_NA_TRN_NA_AIRC_NA_NA_SEATMPG.A | D39: seat mpg | F39: 85.368492 | G39: 85.782234 | H39: 86.453064 | I39: 87.12735 | J39: 87.815926 | K39: 88.497086 | L39: 89.183655 | M39: 89.886848 | N39: 90.639893 | O39: 91.399002 | P39: 92.155807 | Q39: 92.914574 | R39: 93.675323 | S39: 94.433296 | T39: 95.211731 | U39: 95.983521 | V39: 96.76857 | W39: 97.563377 | X39: 98.389313 | Y39: 99.21096 | Z39: 100.03321 | AA39: 100.86144 | AB39: 101.69376 | AC39: 102.53442 | AD39: 103.37976 | AE39: 104.222 | AF39: 105.06316 | AG39: 0.008
A40: (ton miles/thousand Btu)
A41: Rail | B41: Transportation: Energy Efficiency Indicators: Rail: Alternative Transportation | C41: AEO.2025.ALTTRNP.EFI_NA_TRN_NA_RAIL_NA_NA_TONMLPTHBTU.A | D41: ton miles/thousand Btu | F41: 3.37345 | G41: 3.37701 | H41: 3.380574 | I41: 3.384142 | J41: 3.387713 | K41: 3.391289 | L41: 3.394868 | M41: 3.398451 | N41: 3.402037 | O41: 3.405628 | P41: 3.409222 | Q41: 3.41282 | R41: 3.416422 | S41: 3.420027 | T41: 3.423637 | U41: 3.42725 | V41: 3.430867 | W41: 3.434488 | X41: 3.438113 | Y41: 3.441741 | Z41: 3.445373 | AA41: 3.44901 | AB41: 3.452649 | AC41: 3.456293 | AD41: 3.459941 | AE41: 3.463593 | AF41: 3.467248 | AG41: 0.001
A42: Domestic Shipping | B42: Transportation: Energy Efficiency Indicators: Domestic Shipping: Alternative Transportation | C42: AEO.2025.ALTTRNP.EFI_NA_TRN_NA_DMT_NA_NA_TONMLPTHBTU.A | D42: ton miles/thousand Btu | F42: 4.857779 | G42: 4.876665 | H42: 4.895624 | I42: 4.914657 | J42: 4.933764 | K42: 4.952945 | L42: 4.9722 | M42: 4.991531 | N42: 5.010937 | O42: 5.030418 | P42: 5.049975 | Q42: 5.069608 | R42: 5.089317 | S42: 5.109103 | T42: 5.128966 | U42: 5.148906 | V42: 5.168923 | W42: 5.189019 | X42: 5.209192 | Y42: 5.229445 | Z42: 5.249775 | AA42: 5.270185 | AB42: 5.290674 | AC42: 5.311243 | AD42: 5.331892 | AE42: 5.352621 | AF42: 5.37343 | AG42: 0.004
A43: Energy Use by Mode
...

Sheet AEO 2022 Table 7
B1: highogs.d120120a | C1: 2021 | D1: 2022 | E1: 2023 | F1: 2024 | G1: 2025 | H1: 2026 | I1: 2027 | J1: 2028 | K1: 2029 | L1: 2030 | M1: 2031 | N1: 2032 | O1: 2033 | P1: 2034 | Q1: 2035 | R1: 2036 | S1: 2037 | T1: 2038 | U1: 2039 | V1: 2040 | W1: 2041 | X1: 2042 | Y1: 2043 | Z1: 2044 | AA1: 2045 | AB1: 2046 | AC1: 2047 | AD1: 2048 | AE1: 2049 | AF1: 2050
C3: Annual Energy Outlook 2021
C4: ref2021 | F4: Reference case
C5: d113020a
D6: January 2021
A10: TKI000 | B10: 7. Transportation Sector Key Indicators and Delivered Energy Consumption | AG10: Compound
AG11: Growth
AG12: 2020-2050
B13: Key Indicators and Consumption | C13: 2021 | D13: 2022 | E13: 2023 | F13: 2024 | G13: 2025 | H13: 2026 | I13: 2027 | J13: 2028 | K13: 2029 | L13: 2030 | M13: 2031 | N13: 2032 | O13: 2033 | P13: 2034 | Q13: 2035 | R13: 2036 | S13: 2037 | T13: 2038 | U13: 2039 | V13: 2040 | W13: 2041 | X13: 2042 | Y13: 2043 | Z13: 2044 | AA13: 2045 | AB13: 2046 | AC13: 2047 | AD13: 2048 | AE13: 2049 | AF13: 2050 | AG13: (percent)
B15: Key Indicators
B16: Travel Indicators
B17: (billion vehicle miles traveled)
A18: TKI000:ba_Light-DutyVeh | B18: Light-Duty Vehicles less than 8,501 pounds | C18: 2761.1487 | D18: 2887.3313 | E18: 2986.1375 | F18: 3033.4624 | G18: 3075.9688 | H18: 3112.4636 | I18: 3140.5366 | J18: 3162.593 | K18: 3183.811 | L18: 3206.8018 | M18: 3229.7073 | N18: 3247.4204 | O18: 3266.4207 | P18: 3283.7412 | Q18: 3299.2346 | R18: 3314.6108 | S18: 3331.2617 | T18: 3348.0293 | U18: 3367.125 | V18: 3386.949 | W18: 3405.9556 | X18: 3425.8684 | Y18: 3445.7124 | Z18: 3465.4507 | AA18: 3486.7061 | AB18: 3510.4651 | AC18: 3534.4812 | AD18: 3558.8704 | AE18: 3584.9614 | AF18: 3613.5239 | AG18: 0.009
A19: TKI000:ba_CommercialLig | B19: Commercial Light Trucks 1/ | C19: 100.76003 | D19: 104.34176 | E19: 106.70262 | F19: 108.00214 | G19: 109.34573 | H19: 110.56496 | I19: 111.42751 | J19: 112.36408 | K19: 113.47929 | L19: 114.62598 | M19: 115.78786 | N19: 117.00378 | O19: 118.26071 | P19: 119.48289 | Q19: 120.7066 | R19: 121.99136 | S19: 123.41512 | T19: 124.85188 | U19: 126.28014 | V19: 127.69122 | W19: 129.20485 | X19: 130.79395 | Y19: 132.42688 | Z19: 134.00609 | AA19: 135.59607 | AB19: 137.31485 | AC19: 138.90479 | AD19: 140.36012 | AE19: 142.02193 | AF19: 144.02313 | AG19: 0.012
A20: TKI000:ba_FreightTrucks | B20: Freight Trucks greater than 10,000 pounds | C20: 296.81839 | D20: 304.25449 | E20: 308.97504 | F20: 312.70242 | G20: 316.88568 | H20: 320.48059 | I20: 323.30453 | J20: 326.69177 | K20: 330.38946 | L20: 333.86133 | M20: 337.28406 | N20: 340.79715 | O20: 344.26349 | P20: 347.5257 | Q20: 350.95914 | R20: 354.45807 | S20: 358.38226 | T20: 362.35556 | U20: 366.2616 | V20: 370.20163 | W20: 374.51642 | X20: 379.08896 | Y20: 383.45093 | Z20: 387.78918 | AA20: 392.14526 | AB20: 396.80841 | AC20: 400.81616 | AD20: 404.24228 | AE20: 408.71432 | AF20: 414.21069 | AG20: 0.012
B21: (billion passenger miles traveled)
A22: TKI000:buspassmiles | B22: Bus Transportation | C22: 151.30966 | D22: 173.16789 | E22: 184.76592 | F22: 191.65541 | G22: 196.21399 | H22: 199.3981 | I22: 201.69253 | J22: 203.40639 | K22: 204.7121 | L22: 205.76692 | M22: 206.62942 | N22: 207.27484 | O22: 207.8185 | P22: 208.29555 | Q22: 208.67419 | R22: 209.06363 | S22: 209.5192 | T22: 209.89679 | U22: 210.00269 | V22: 210.10393 | W22: 210.12295 | X22: 210.09636 | Y22: 210.06598 | Z22: 210.01566 | AA22: 209.94398 | AB22: 209.88408 | AC22: 209.77901 | AD22: 209.63933 | AE22: 209.48929 | AF22: 209.347 | AG22: 0.011
A23: TKI000:railpassmiles | B23: Passenger Rail | C23: 29.706352 | D23: 33.420921 | E23: 35.774769 | F23: 37.825356 | G23: 39.433685 | H23: 40.788967 | I23: 41.767357 | J23: 42.560257 | K23: 43.304031 | L23: 44.145664 | M23: 44.963547 | N23: 45.652962 | O23: 46.319397 | P23: 46.919537 | Q23: 47.423344 | R23: 47.944431 | S23: 48.515842 | T23: 49.068516 | U23: 49.548981 | V23: 50.127491 | W23: 50.601322 | X23: 51.080406 | Y23: 51.618813 | Z23: 52.163063 | AA23: 52.755924 | AB23: 53.42416 | AC23: 53.984158 | AD23: 54.50843 | AE23: 55.108772 | AF23: 55.777504 | AG23: 0.022
B24: (billion seat miles available)
A25: TKI000:ba_Air | B25: Air | C25: 884.81805 | D25: 1076.55 | E25: 1230.1667 | F25: 1281.0972 | G25: 1332.4701 | H25: 1370.9828 | I25: 1398.9177 | J25: 1427.2495 | K25: 1459.7749 | L25: 1496.7294 | M25: 1531.1088 | N25: 1567.3237 | O25: 1606.1002 | P25: 1644.3704 | Q25: 1681.6504 | R25: 1717.8458 | S25: 1756.6516 | T25: 1794.5098 | U25: 1835.0491 | V25: 1878.3563 | W25: 1916.7485 | X25: 1957.8833 | Y25: 2001.3043 | Z25: 2045.0242 | AA25: 2092.8052 | AB25: 2142.4402 | AC25: 2188.459 | AD25: 2235.0183 | AE25: 2287.7986 | AF25: 2344.385 | AG25: 0.034
B26: (billion ton miles traveled)
A27: TKI000:ba_Rail | B27: Rail | C27: 1644.4915 | D27: 1665.1613 | E27: 1687.2128 | F27: 1584.5679 | G27: 1618.0447 | H27: 1660.0645 | I27: 1667.3862 | J27: 1673.5901 | K27: 1678.8776 | L27: 1688.5286 | M27: 1699.8828 | N27: 1711.3606 | O27: 1724.6821 | P27: 1718.1174 | Q27: 1722.3843 | R27: 1715.6056 | S27: 1728.4023 | T27: 1737.8145 | U27: 1747.3446 | V27: 1754.1726 | W27: 1763.5247 | X27: 1775.6241 | Y27: 1781.4792 | Z27: 1785.2306 | AA27: 1792.4877 | AB27: 1803.1855 | AC27: 1810.229 | AD27: 1819.6707 | AE27: 1831.4158 | AF27: 1852.35 | AG27: 0.004
A28: TKI000:ba_DomesticShipp | B28: Domestic Shipping | C28: 340.48685 | D28: 355.078 | E28: 354.80612 | F28: 347.34994 | G28: 340.59833 | H28: 332.84692 | I28: 323.82996 | J28: 315.29077 | K28: 306.4082 | L28: 297.53073 | M28: 293.53958 | N28: 289.49127 | O28: 285.82245 | P28: 281.63907 | Q28: 277.23456 | R28: 273.04852 | S28: 269.29669 | T28: 265.319 | U28: 261.74301 | V28: 258.02158 | W28: 257.14194 | X28: 256.13333 | Y28: 254.95567 | Z28: 253.95633 | AA28: 252.95215 | AB28: 252.08273 | AC28: 250.62955 | AD28: 248.75684 | AE28: 247.7997 | AF28: 247.80908 | AG28: -0.011
B30: Energy Efficiency Indicators
B31: (miles per gallon)
A32: TKI000:ca_AvgCAFEStand | B32: New Light-Duty Vehicle CAFE Standard 2/ | C32: 35.285992 | D32: 35.48703 | E32: 35.771912 | F32: 36.135601 | G32: 36.515312 | H32: 37.058449 | I32: 37.01659 | J32: 36.995026 | K32: 36.98127 | L32: 36.99622 | M32: 37.031643 | N32: 37.041542 | O32: 37.047226 | P32: 37.049618 | Q32: 37.040478 | R32: 37.033859 | S32: 37.025627 | T32: 37.023102 | U32: 37.003475 | V32: 36.994915 | W32: 36.983158 | X32: 36.964703 | Y32: 36.957966 | Z32: 36.952953 | AA32: 36.939468 | AB32: 36.932568 | AC32: 36.915142 | AD32: 36.891186 | AE32: 36.867813 | AF32: 36.844318 | AG32: 0.001
A33: TKI000:ca_CarCAFEStand | B33: New Car 2/ | C33: 44.288506 | D33: 44.826138 | E33: 45.45166 | F33: 46.205555 | G33: 46.881027 | H33: 47.673538 | I33: 47.678375 | J33: 47.68045 | K33: 47.684368 | L33: 47.699383 | M33: 47.710827 | N33: 47.710827 | O33: 47.710827 | P33: 47.710827 | Q33: 47.710827 | R33: 47.710827 | S33: 47.711578 | T33: 47.714207 | U33: 47.714207 | V33: 47.715466 | W33: 47.715603 | X33: 47.715603 | Y33: 47.71888 | Z33: 47.719818 | AA33: 47.719818 | AB33: 47.721157 | AC33: 47.721157 | AD33: 47.721157 | AE33: 47.721157 | AF33: 47.721333 | AG33: 0.003
A34: TKI000:ca_TwukCAFEStand | B34: New Light Truck 2/ | C34: 31.772453 | D34: 32.124016 | E34: 32.563663 | F34: 33.014378 | G34: 33.490173 | H34: 34.05373 | I34: 34.053749 | J34: 34.053802 | K34: 34.053837 | L34: 34.053837 | M34: 34.053837 | N34: 34.053913 | O34: 34.053944 | P34: 34.053978 | Q34: 34.054016 | R34: 34.054024 | S34: 34.054043 | T34: 34.054043 | U34: 34.054092 | V34: 34.054092 | W34: 34.054096 | X34: 34.054131 | Y34: 34.054131 | Z34: 34.054131 | AA34: 34.054165 | AB34: 34.054165 | AC34: 34.054195 | AD34: 34.054214 | AE34: 34.054226 | AF34: 34.054241 | AG34: 0.002
A35: TKI000:ca_NewVehCred | B35: Compliance New Light-Duty Vehicle 3/ | C35: 36.320473 | D35: 37.31142 | E35: 37.662174 | F35: 38.010811 | G35: 38.094296 | H35: 38.247921 | I35: 38.293079 | J35: 38.352066 | K35: 38.418518 | L35: 38.54631 | M35: 38.726295 | N35: 38.866302 | O35: 38.983082 | P35: 39.093426 | Q35: 39.1922 | R35: 39.302681 | S35: 39.416943 | T35: 39.533672 | U35: 39.591755 | V35: 39.675838 | W35: 39.750217 | X35: 39.796734 | Y35: 39.879173 | Z35: 39.96608 | AA35: 40.016975 | AB35: 40.087498 | AC35: 40.122173 | AD35: 40.129021 | AE35: 40.139771 | AF35: 40.152401 | AG35: 0.003
A36: TKI000:ca_NewCarCred | B36: New Car 3/ | C36: 45.475075 | D36: 46.463356 | E36: 46.871098 | F36: 47.613346 | G36: 48.15469 | H36: 48.952316 | I36: 49.009914 | J36: 48.983555 | K36: 49.005871 | L36: 49.1185 | M36: 49.276249 | N36: 49.423874 | O36: 49.562927 | P36: 49.715073 | Q36: 49.873493 | R36: 50.02845 | S36: 50.20089 | T36: 50.381207 | U36: 50.512337 | V36: 50.639797 | W36: 50.785503 | X36: 50.896545 | Y36: 51.036186 | Z36: 51.184166 | AA36: 51.303078 | AB36: 51.434132 | AC36: 51.549774 | AD36: 51.631973 | AE36: 51.718174 | AF36: 51.811989 | AG36: 0.005
A37: TKI000:ca_NewTwukCred | B37: New Light Truck 3/ | C37: 32.735344 | D37: 33.951099 | E37: 34.524212 | F37: 34.952869 | G37: 35.098633 | H37: 35.197926 | I37: 35.290627 | J37: 35.391632 | K37: 35.482613 | L37: 35.596081 | M37: 35.737183 | N37: 35.860985 | O37: 35.963947 | P37: 36.060459 | Q37: 36.155796 | R37: 36.262741 | S37: 36.372746 | T37: 36.4776 | U37: 36.543522 | V37: 36.62775 | W37: 36.700649 | X37: 36.755989 | Y37: 36.834328 | Z37: 36.913742 | AA37: 36.966965 | AB37: 37.033054 | AC37: 37.073078 | AD37: 37.095291 | AE37: 37.1208 | AF37: 37.147499 | AG37: 0.004
A38: TKI000:ca_TestedNewVeh | B38: Tested New Light-Duty Vehicle 4/ | C38: 36.097652 | D38: 36.890865 | E38: 37.16309 | F38: 37.471909 | G38: 37.548306 | H38: 37.693558 | I38: 37.730827 | J38: 37.779949 | K38: 37.82983 | L38: 37.92981 | M38: 38.074917 | N38: 38.1805 | O38: 38.265446 | P38: 38.343956 | Q38: 38.411659 | R38: 38.491077 | S38: 38.574333 | T38: 38.658054 | U38: 38.691067 | V38: 38.74736 | W38: 38.795506 | X38: 38.81963 | Y38: 38.873913 | Z38: 38.931656 | AA38: 38.959419 | AB38: 39.003712 | AC38: 39.018578 | AD38: 39.010792 | AE38: 39.006245 | AF38: 39.002537 | AG38: 0.003
A39: TKI000:ca_TestedNewCar | B39: New Car 4/ | C39: 45.096481 | D39: 45.979137 | E39: 46.313679 | F39: 46.990833 | G39: 47.515671 | H39: 48.291649 | I39: 48.344982 | J39: 48.315689 | K39: 48.322018 | L39: 48.394592 | M39: 48.506691 | N39: 48.606041 | O39: 48.697697 | P39: 48.801441 | Q39: 48.908657 | R39: 49.014748 | S39: 49.136864 | T39: 49.263721 | U39: 49.347969 | V39: 49.429173 | W39: 49.526897 | X39: 49.593983 | Y39: 49.683327 | Z39: 49.77837 | AA39: 49.849922 | AB39: 49.930515 | AC39: 50.000229 | AD39: 50.043533 | AE39: 50.089653 | AF39: 50.139729 | AG39: 0.004
A40: TKI000:ca_TestedNewTwuk | B40: New Light Truck 4/ | C40: 32.562687 | D40: 33.557835 | E40: 34.050751 | F40: 34.445057 | G40: 34.584492 | H40: 34.677776 | I40: 34.761444 | J40: 34.851055 | K40: 34.925472 | L40: 35.014309 | M40: 35.12392 | N40: 35.217022 | O40: 35.292133 | P40: 35.36097 | Q40: 35.429878 | R40: 35.509933 | S40: 35.593349 | T40: 35.669994 | U40: 35.715256 | V40: 35.775749 | W40: 35.826942 | X40: 35.864029 | Y40: 35.918907 | Z40: 35.974251 | AA40: 36.00901 | AB40: 36.053822 | AC40: 36.07869 | AD40: 36.090065 | AE40: 36.104107 | AF40: 36.118683 | AG40: 0.004
A41: TKI000:ca_OnRoadNewVeh | B41: On-Road New Light-Duty Vehicle 5/ | C41: 29.44529 | D41: 30.091688 | E41: 30.313065 | F41: 30.564369 | G41: 30.626116 | H41: 30.744225 | I41: 30.774488 | J41: 30.814499 | K41: 30.85515 | L41: 30.93675 | M41: 31.055231 | N41: 31.141388 | O41: 31.210691 | P41: 31.274731 | Q41: 31.329922 | R41: 31.394674 | S41: 31.462549 | T41: 31.530819 | U41: 31.557674 | V41: 31.603556 | W41: 31.642776 | X41: 31.662386 | Y41: 31.706629 | Z41: 31.753708 | AA41: 31.776299 | AB41: 31.812397 | AC41: 31.824455 | AD41: 31.818008 | AE41: 31.814219 | AF41: 31.8111 | AG41: 0.003
A42: TKI000:ca_OnRoadNewCar | B42: New Car 5/ | C42: 36.82645 | D42: 37.547241 | E42: 37.820435 | F42: 38.373409 | G42: 38.801998 | H42: 39.435673 | I42: 39.479225 | J42: 39.455303 | K42: 39.460472 | L42: 39.519737 | M42: 39.611279 | N42: 39.69241 | O42: 39.767258 | P42: 39.851978 | Q42: 39.939529 | R42: 40.026165 | S42: 40.125889 | T42: 40.229481 | U42: 40.298279 | V42: 40.36459 | W42: 40.444393 | X42: 40.499176 | Y42: 40.572136 | Z42: 40.64975 | AA42: 40.708183 | AB42: 40.773994 | AC42: 40.830925 | AD42: 40.866287 | AE42: 40.90395 | AF42: 40.944843 | AG42: 0.004
A43: TKI000:ca_OnRoadNewTwuk | B43: New Light Truck 5/ | C43: 26.550249 | D43: 27.36165 | E43: 27.763554 | F43: 28.085054 | G43: 28.198744 | H43: 28.274803 | I43: 28.343023 | J43: 28.416088 | K43: 28.476765 | L43: 28.549198 | M43: 28.638571 | N43: 28.714481 | O43: 28.775724 | P43: 28.83185 | Q43: 28.888037 | R43: 28.95331 | S43: 29.021324 | T43: 29.083817 | U43: 29.120722 | V43: 29.170044 | W43: 29.211786 | X43: 29.242025 | Y43: 29.28677 | Z43: 29.331894 | AA43: 29.360237 | AB43: 29.396774 | AC43: 29.417049 | AD43: 29.426325 | AE43: 29.437775 | AF43: 29.449659 | AG43: 0.004
... A47: TKI000:ca_FreightTruck | B47: Freight Truck | C47: 7.331892 | D47: 7.410312 | E47: 7.497923 | F47: 7.5963 | G47: 7.70782 | H47: 7.832913 | I47: 7.97052 | J47: 8.109589 | K47: 8.254834 | L47: 8.403061 | M47: 8.551556 | N47: 8.69581 | O47: 8.830752 | P47: 8.955747 | Q47: 9.070722 | R47: 9.177202 | S47: 9.275028 | T47: 9.363853 | U47: 9.444804 | V47: 9.51915 | W47: 9.58819 | X47: 9.649012 | Y47: 9.704254 | Z47: 9.754515 | AA47: 9.801952 | AB47: 9.848245 | AC47: 9.894052 | AD47: 9.940031 | AE47: 9.985973 | AF47: 10.031261 | AG47: 0.011
B48: (seat miles per gallon)
A49: TKI000:ca_Aircraft | B49: Aircraft | C49: 73.643883 | D49: 74.164284 | E49: 74.683517 | F49: 75.120308 | G49: 75.583763 | H49: 75.871498 | I49: 76.308502 | J49: 76.801476 | K49: 77.308174 | L49: 77.856262 | M49: 78.434464 | N49: 79.126999 | O49: 79.792549 | P49: 80.511719 | Q49: 81.242912 | R49: 81.987068 | S49: 82.759789 | T49: 83.544899 | U49: 84.319893 | V49: 85.114548 | W49: 85.926819 | X49: 86.77433 | Y49: 87.609406 | Z49: 88.41713 | AA49: 89.23912 | AB49: 90.056198 | AC49: 90.860878 | AD49: 91.651962 | AE49: 92.4216 | AF49: 93.179382 | AG49: 0.008
...

Sheet AEO 2021 Table 7
B1: highogs.d120120a | C1: 2020 | D1: 2021 | E1: 2022 | F1: 2023 | G1: 2024 | H1: 2025 | I1: 2026 | J1: 2027 | K1: 2028 | L1: 2029 | M1: 2030 | N1: 2031 | O1: 2032 | P1: 2033 | Q1: 2034 | R1: 2035 | S1: 2036 | T1: 2037 | U1: 2038 | V1: 2039 | W1: 2040 | X1: 2041 | Y1: 2042 | Z1: 2043 | AA1: 2044 | AB1: 2045 | AC1: 2046 | AD1: 2047 | AE1: 2048 | AF1: 2049 | AG1: 2050
C3: Report | D3: Annual Energy Outlook 2021
C4: Scenario | D4: ref2021 | G4: Reference case
C5: Datekey | D5: d113020a
C6: Release Date | E6: January 2021
A10: TKI000 | B10: 7. Transportation Sector Key Indicators and Delivered Energy Consumption | AH10: Compound
AH11: Growth
AH12: 2020-2050
B13: Key Indicators and Consumption | C13: 2020 | D13: 2021 | E13: 2022 | F13: 2023 | G13: 2024 | H13: 2025 | I13: 2026 | J13: 2027 | K13: 2028 | L13: 2029 | M13: 2030 | N13: 2031 | O13: 2032 | P13: 2033 | Q13: 2034 | R13: 2035 | S13: 2036 | T13: 2037 | U13: 2038 | V13: 2039 | W13: 2040 | X13: 2041 | Y13: 2042 | Z13: 2043 | AA13: 2044 | AB13: 2045 | AC13: 2046 | AD13: 2047 | AE13: 2048 | AF13: 2049 | AG13: 2050 | AH13: (percent)
B15: Key Indicators
B16: Travel Indicators
B17: (billion vehicle miles traveled)
A18: TKI000:ba_Light-DutyVeh | B18: Light-Duty Vehicles less than 8,501 pounds | C18: 2628.8213 | D18: 2807.2766 | E18: 2862.5334 | F18: 2927.623 | G18: 2985.1787 | H18: 3035.5583 | I18: 3076.646 | J18: 3107.3425 | K18: 3133.9348 | L18: 3153.6963 | M18: 3170.1406 | N18: 3182.3604 | O18: 3194.3308 | P18: 3208.3691 | Q18: 3223.0125 | R18: 3240.585 | S18: 3258.4961 | T18: 3274.8767 | U18: 3290.0166 | V18: 3306.9768 | W18: 3326.3066 | X18: 3344.3862 | Y18: 3362.8257 | Z18: 3380.6958 | AA18: 3396.752 | AB18: 3412.0305 | AC18: 3428.1084 | AD18: 3442.5149 | AE18: 3458.3401 | AF18: 3474.7087 | AG18: 3490.9399 | AH18: 0.009499
A19: TKI000:ba_CommercialLig | B19: Commercial Light Trucks 1/ | C19: 89.884674 | D19: 93.705605 | E19: 96.386086 | F19: 98.338295 | G19: 100.59341 | H19: 102.85941 | I19: 104.50481 | J19: 105.69051 | K19: 106.73648 | L19: 107.65262 | M19: 108.58299 | N19: 109.54169 | O19: 110.61884 | P19: 111.70705 | Q19: 112.95861 | R19: 114.4644 | S19: 115.90713 | T19: 117.2149 | U19: 118.58162 | V19: 120.04366 | W19: 121.52813 | X19: 123.15266 | Y19: 124.79562 | Z19: 126.54729 | AA19: 128.13809 | AB19: 129.78653 | AC19: 131.39938 | AD19: 132.81888 | AE19: 134.41592 | AF19: 136.18376 | AG19: 138.01 | AH19: 0.014396
A20: TKI000:ba_FreightTrucks | B20: Freight Trucks greater than 10,000 pounds | C20: 274.54938 | D20: 282.81525 | E20: 293.31253 | F20: 299.26825 | G20: 306.24057 | H20: 313.39252 | I20: 318.20425 | J20: 321.86676 | K20: 325.49912 | L20: 328.91818 | M20: 332.87759 | N20: 337.04804 | O20: 341.41943 | P20: 345.24298 | Q20: 349.75104 | R20: 355.3486 | S20: 360.47449 | T20: 365.30786 | U20: 370.46982 | V20: 375.98251 | W20: 381.01727 | X20: 386.70856 | Y20: 392.7948 | Z20: 399.70087 | AA20: 405.64847 | AB20: 411.79804 | AC20: 417.07053 | AD20: 422.22894 | AE20: 428.00507 | AF20: 434.11798 | AG20: 440.79153 | AH20: 0.015907
B21: (billion passenger miles traveled)
A22: TKI000:buspassmiles | B22: Bus Transportation | C22: 108.32251 | D22: 134.82925 | E22: 154.71742 | F22: 169.65283 | G22: 180.92081 | H22: 189.4493 | I22: 195.91775 | J22: 200.87158 | K22: 204.4294 | L22: 207.17819 | M22: 209.42627 | N22: 211.01544 | O22: 212.35484 | P22: 213.3685 | Q22: 214.16457 | R22: 214.70816 | S22: 215.16942 | T22: 215.53513 | U22: 215.80548 | V22: 215.98587 | W22: 216.16197 | X22: 216.26544 | Y22: 216.33122 | Z22: 216.37845 | AA22: 216.40999 | AB22: 216.44157 | AC22: 216.45151 | AD22: 216.46837 | AE22: 216.483 | AF22: 216.55254 | AG22: 216.64348 | AH22: 0.023374
A23: TKI000:railpassmiles | B23: Passenger Rail | C23: 24.970692 | D23: 29.653244 | E23: 33.486446 | F23: 36.386101 | G23: 38.577961 | H23: 40.222988 | I23: 41.396164 | J23: 42.264778 | K23: 42.515728 | L23: 42.713291 | M23: 43.137005 | N23: 43.343742 | O23: 43.818241 | P23: 44.274139 | Q23: 44.835865 | R23: 45.310886 | S23: 45.831734 | T23: 46.32793 | U23: 46.816154 | V23: 47.317448 | W23: 47.980492 | X23: 48.58215 | Y23: 49.164021 | Z23: 49.763081 | AA23: 50.334721 | AB23: 50.97802 | AC23: 51.558666 | AD23: 52.079247 | AE23: 52.647175 | AF23: 53.282265 | AG23: 53.912506 | AH23: 0.025987
B24: (billion seat miles available)
A25: TKI000:ba_Air | B25: Air | C25: 738.85895 | D25: 1081.6603 | E25: 1215.7373 | F25: 1284.3009 | G25: 1340.2419 | H25: 1397.254 | I25: 1430.9814 | J25: 1455.4497 | K25: 1476.5328 | L25: 1495.9988 | M25: 1516.3666 | N25: 1539.9563 | O25: 1569.8956 | P25: 1600.4498 | Q25: 1634.8596 | R25: 1672.6685 | S25: 1707.1351 | T25: 1738.4458 | U25: 1770.8867 | V25: 1807.5973 | W25: 1848.892 | X25: 1889.7706 | Y25: 1930.5969 | Z25: 1971.072 | AA25: 2010.4889 | AB25: 2052.9485 | AC25: 2092.6599 | AD25: 2129.1379 | AE25: 2171.0725 | AF25: 2213.2192 | AG25: 2256.3169 | AH25: 0.037914
B26: (billion ton miles traveled)
A27: TKI000:ba_Rail | B27: Rail | C27: 1508.557 | D27: 1600.7733 | E27: 1616.5277 | F27: 1618.1086 | G27: 1617.9658 | H27: 1567.8839 | I27: 1587.1537 | J27: 1586.3214 | K27: 1606.0509 | L27: 1623.5897 | M27: 1641.5112 | N27: 1654.2195 | O27: 1664.4609 | P27: 1678.1671 | Q27: 1686.5093 | R27: 1700.8228 | S27: 1714.3484 | T27: 1725.9465 | U27: 1730.047 | V27: 1747.595 | W27: 1753.4669 | X27: 1765.8125 | Y27: 1783.1677 | Z27: 1804.6465 | AA27: 1808.4172 | AB27: 1822.5868 | AC27: 1832.4125 | AD27: 1846.7275 | AE27: 1860.8992 | AF27: 1876.0131 | AG27: 1898.7479 | AH27: 0.007697
A28: TKI000:ba_DomesticShipp | B28: Domestic Shipping | C28: 347.68133 | D28: 359.32346 | E28: 357.10059 | F28: 354.90668 | G28: 352.6954 | H28: 348.07819 | I28: 341.28058 | J28: 333.10046 | K28: 325.25259 | L28: 316.86505 | M28: 308.73145 | N28: 305.11627 | O28: 301.85187 | P28: 298.30835 | Q28: 295.38019 | R28: 292.62634 | S28: 289.63 | T28: 286.27258 | U28: 282.6651 | V28: 279.71716 | W28: 276.01688 | X28: 275.42545 | Y28: 275.00784 | Z28: 275.36859 | AA28: 274.91849 | AB28: 274.56326 | AC28: 273.54471 | AD28: 272.61859 | AE28: 271.43494 | AF28: 270.55728 | AG28: 270.13117 | AH28: -0.008377
B30: Energy Efficiency Indicators
B31: (miles per gallon)
A32: TKI000:ca_AvgCAFEStand | B32: New Light-Duty Vehicle CAFE Standard 2/ | C32: 34.471165 | D32: 35.386478 | E32: 36.015511 | F32: 36.532135 | G32: 36.999756 | H32: 37.485561 | I32: 38.067947 | J32: 38.072563 | K32: 38.080814 | L32: 38.095245 | M32: 38.18074 | N32: 38.191765 | O32: 38.206318 | P32: 38.220623 | Q32: 38.249493 | R32: 38.23008 | S32: 38.209507 | T32: 38.204479 | U32: 38.204224 | V32: 38.187893 | W32: 38.180141 | X32: 38.173969 | Y32: 38.160957 | Z32: 38.151768 | AA32: 38.148342 | AB32: 38.153297 | AC32: 38.143864 | AD32: 38.134365 | AE32: 38.120548 | AF32: 38.116928 | AG32: 38.114223 | AH32: 0.003354
A33: TKI000:ca_CarCAFEStand | B33: New Car 2/ | C33: 42.096588 | D33: 44.275085 | E33: 44.804096 | F33: 45.431927 | G33: 46.163593 | H33: 46.83271 | I33: 47.617275 | J33: 47.640335 | K33: 47.640335 | L33: 47.644814 | M33: 47.681995 | N33: 47.681995 | O33: 47.681995 | P33: 47.681995 | Q33: 47.681995 | R33: 47.681995 | S33: 47.681995 | T33: 47.681995 | U33: 47.681995 | V33: 47.681995 | W33: 47.681995 | X33: 47.681995 | Y33: 47.681995 | Z33: 47.683205 | AA33: 47.684814 | AB33: 47.687138 | AC33: 47.687138 | AD33: 47.687138 | AE33: 47.687138 | AF33: 47.689449 | AG33: 47.689449 | AH33: 0.004167
A34: TKI000:ca_TwukCAFEStand | B34: New Light Truck 2/ | C34: 30.906752 | D34: 31.515783 | E34: 31.942911 | F34: 32.461285 | G34: 32.91795 | H34: 33.400791 | I34: 33.955074 | J34: 33.955074 | K34: 33.955074 | L34: 33.955074 | M34: 33.955074 | N34: 33.955093 | O34: 33.955093 | P34: 33.955093 | Q34: 33.955093 | R34: 33.955128 | S34: 33.955128 | T34: 33.955128 | U34: 33.955128 | V34: 33.955128 | W34: 33.955128 | X34: 33.955128 | Y34: 33.955128 | Z34: 33.955128 | AA34: 33.955128 | AB34: 33.955128 | AC34: 33.955128 | AD34: 33.955128 | AE34: 33.955128 | AF34: 33.955128 | AG34: 33.955128 | AH34: 0.00314
A35: TKI000:ca_NewVehCred | B35: Compliance New Light-Duty Vehicle 3/ | C35: 35.428043 | D35: 36.588161 | E35: 37.27243 | F35: 37.693687 | G35: 38.000156 | H35: 38.414772 | I35: 38.930225 | J35: 39.067493 | K35: 39.131561 | L35: 39.187084 | M35: 39.367001 | N35: 39.458767 | O35: 39.570412 | P35: 39.688381 | Q35: 39.842903 | R35: 39.925739 | S35: 40.007633 | T35: 40.122059 | U35: 40.263226 | V35: 40.363659 | W35: 40.483315 | X35: 40.567554 | Y35: 40.636898 | Z35: 40.715225 | AA35: 40.813824 | AB35: 40.933929 | AC35: 41.032745 | AD35: 41.136253 | AE35: 41.233734 | AF35: 41.366283 | AG35: 41.510693 | AH35: 0.005296
A36: TKI000:ca_NewCarCred | B36: New Car 3/ | C36: 43.264011 | D36: 45.133469 | E36: 45.638382 | F36: 46.329559 | G36: 46.974045 | H36: 47.544498 | I36: 48.288284 | J36: 48.41925 | K36: 48.519196 | L36: 48.602192 | M36: 48.75803 | N36: 48.944359 | O36: 49.116051 | P36: 49.343533 | Q36: 49.588879 | R36: 49.838387 | S36: 50.062164 | T36: 50.324268 | U36: 50.609341 | V36: 50.887779 | W36: 51.161552 | X36: 51.375084 | Y36: 51.577618 | Z36: 51.784939 | AA36: 52.021469 | AB36: 52.278286 | AC36: 52.554256 | AD36: 52.823685 | AE36: 53.105881 | AF36: 53.415283 | AG36: 53.766708 | AH36: 0.007271
A37: TKI000:ca_NewTwukCred | B37: New Light Truck 3/ | C37: 31.76507 | D37: 32.790131 | E37: 33.304337 | F37: 33.675228 | G37: 33.948895 | H37: 34.370636 | I37: 34.850887 | J37: 34.987331 | K37: 35.027725 | L37: 35.055889 | M37: 35.139996 | N37: 35.184067 | O37: 35.253815 | P37: 35.313755 | Q37: 35.395432 | R37: 35.447819 | S37: 35.509632 | T37: 35.58049 | U37: 35.672146 | V37: 35.736599 | W37: 35.81567 | X37: 35.86631 | Y37: 35.911537 | Z37: 35.962078 | AA37: 36.021683 | AB37: 36.09063 | AC37: 36.147751 | AD37: 36.213341 | AE37: 36.274784 | AF37: 36.358318 | AG37: 36.442936 | AH37: 0.00459
A38: TKI000:ca_TestedNewVeh | B38: Tested New Light-Duty Vehicle 4/ | C38: 35.306622 | D38: 36.467899 | E38: 37.145805 | F38: 37.564754 | G38: 37.869587 | H38: 38.261166 | I38: 38.678329 | J38: 38.78212 | K38: 38.833714 | L38: 38.876083 | M38: 39.031017 | N38: 39.097122 | O38: 39.178814 | P38: 39.263397 | Q38: 39.380604 | R38: 39.428646 | S38: 39.476784 | T38: 39.553841 | U38: 39.655148 | V38: 39.718605 | W38: 39.800255 | X38: 39.857685 | Y38: 39.902508 | Z38: 39.954895 | AA38: 40.024872 | AB38: 40.112934 | AC38: 40.181061 | AD38: 40.254047 | AE38: 40.320404 | AF38: 40.416508 | AG38: 40.5215 | AH38: 0.004603
A39: TKI000:ca_TestedNewCar | B39: New Car 4/ | C39: 42.996372 | D39: 44.88583 | E39: 45.388092 | F39: 46.068283 | G39: 46.702301 | H39: 47.265957 | I39: 47.99147 | J39: 48.105293 | K39: 48.179577 | L39: 48.231701 | M39: 48.343479 | N39: 48.473526 | O39: 48.589264 | P39: 48.747791 | Q39: 48.918312 | R39: 49.08532 | S39: 49.232788 | T39: 49.410698 | U39: 49.605431 | V39: 49.791992 | W39: 49.975594 | X39: 50.118858 | Y39: 50.253036 | Z39: 50.390747 | AA39: 50.551331 | AB39: 50.726044 | AC39: 50.913406 | AD39: 51.097149 | AE39: 51.287189 | AF39: 51.498287 | AG39: 51.738174 | AH39: 0.006188
